log/output_500_2021_Attention_gpu2.log
wandb: Currently logged in as: pqy000 (pqythu). Use `wandb login --relogin` to force relogin
GPU device ID: 2
newdata/500_2021.npy
2024-09-07 09:46:49.764160: I tensorflow/core/platform/cpu_feature_guard.cc:193] This TensorFlow binary is optimized with oneAPI Deep Neural Network Library (oneDNN) to use the following CPU instructions in performance-critical operations:  AVX2 FMA
To enable them in other operations, rebuild TensorFlow with the appropriate compiler flags.
2024-09-07 09:46:50.734626: W tensorflow/compiler/xla/stream_executor/platform/default/dso_loader.cc:64] Could not load dynamic library 'libnvinfer.so.7'; dlerror: libnvinfer.so.7: cannot open shared object file: No such file or directory; LD_LIBRARY_PATH: /opt/cudnn/lib64:/usr/local/cuda/lib64
2024-09-07 09:46:50.734730: W tensorflow/compiler/xla/stream_executor/platform/default/dso_loader.cc:64] Could not load dynamic library 'libnvinfer_plugin.so.7'; dlerror: libnvinfer_plugin.so.7: cannot open shared object file: No such file or directory; LD_LIBRARY_PATH: /opt/cudnn/lib64:/usr/local/cuda/lib64
2024-09-07 09:46:50.734743: W tensorflow/compiler/tf2tensorrt/utils/py_utils.cc:38] TF-TRT Warning: Cannot dlopen some TensorRT libraries. If you would like to use Nvidia GPU with TensorRT, please make sure the missing libraries mentioned above are installed properly.
wandb: wandb version 0.17.9 is available!  To upgrade, please run:
wandb:  $ pip install wandb --upgrade
wandb: Tracking run with wandb version 0.12.17
wandb: Run data is saved locally in /home/qingyi/GPU20/DeepLOB/wandb/run-20240907_094645-13smjglw
wandb: Run `wandb offline` to turn off syncing.
wandb: Syncing run Attention
wandb: ⭐️ View project at https://wandb.ai/pqythu/futures500
wandb: 🚀 View run at https://wandb.ai/pqythu/futures500/runs/13smjglw
Model(
  (attn): MultiheadAttention(
    (out_proj): NonDynamicallyQuantizableLinear(in_features=10, out_features=10, bias=True)
  )
  (fc): Linear(in_features=10, out_features=5, bias=True)
)
number of parameters: 495
Training start
epoch  1 | time used:  0.65s | train_loss 1.576 | valid loss 1.544 | valid acc 0.364 | mae 1.982 | mse 6.908 | rmse 2.63 | r2 -1.32 | sharp 1.50
epoch  2 | time used:  0.19s | train_loss 1.668 | valid loss 1.839 | valid acc 0.064 | mae 1.710 | mse 3.944 | rmse 1.99 | r2 -0.32 | sharp 1.50
epoch  3 | time used:  0.19s | train_loss 1.732 | valid loss 1.544 | valid acc 0.364 | mae 1.982 | mse 6.908 | rmse 2.63 | r2 -1.32 | sharp 1.50
epoch  4 | time used:  0.20s | train_loss 1.584 | valid loss 1.544 | valid acc 0.364 | mae 1.982 | mse 6.908 | rmse 2.63 | r2 -1.32 | sharp 1.50
epoch  5 | time used:  0.20s | train_loss 1.587 | valid loss 1.544 | valid acc 0.364 | mae 1.982 | mse 6.908 | rmse 2.63 | r2 -1.32 | sharp 1.50
epoch  6 | time used:  0.20s | train_loss 1.585 | valid loss 1.544 | valid acc 0.364 | mae 1.982 | mse 6.908 | rmse 2.63 | r2 -1.32 | sharp 1.50
epoch  7 | time used:  0.20s | train_loss 1.671 | valid loss 1.762 | valid acc 0.141 | mae 1.566 | mse 2.980 | rmse 1.73 | r2 -0.00 | sharp 1.50
epoch  8 | time used:  0.20s | train_loss 1.758 | valid loss 1.762 | valid acc 0.141 | mae 1.566 | mse 2.980 | rmse 1.73 | r2 -0.00 | sharp 1.50
epoch  9 | time used:  0.20s | train_loss 1.763 | valid loss 1.762 | valid acc 0.141 | mae 1.566 | mse 2.980 | rmse 1.73 | r2 -0.00 | sharp 1.50
epoch 10 | time used:  0.19s | train_loss 1.758 | valid loss 1.762 | valid acc 0.141 | mae 1.566 | mse 2.980 | rmse 1.73 | r2 -0.00 | sharp 1.50
saving the model to ./save/2021_500/Attention/checkpoint10.pt
epoch 11 | time used:  0.19s | train_loss 1.758 | valid loss 1.762 | valid acc 0.141 | mae 1.566 | mse 2.980 | rmse 1.73 | r2 -0.00 | sharp 1.50
epoch 12 | time used:  0.19s | train_loss 1.758 | valid loss 1.762 | valid acc 0.141 | mae 1.566 | mse 2.980 | rmse 1.73 | r2 -0.00 | sharp 1.50
epoch 13 | time used:  0.20s | train_loss 1.758 | valid loss 1.762 | valid acc 0.141 | mae 1.566 | mse 2.980 | rmse 1.73 | r2 -0.00 | sharp 1.50
epoch 14 | time used:  0.19s | train_loss 1.610 | valid loss 1.566 | valid acc 0.343 | mae 2.018 | mse 7.052 | rmse 2.66 | r2 -1.37 | sharp 0.00
epoch 15 | time used:  0.20s | train_loss 1.551 | valid loss 1.566 | valid acc 0.343 | mae 2.018 | mse 7.052 | rmse 2.66 | r2 -1.37 | sharp 0.00
epoch 16 | time used:  0.20s | train_loss 1.574 | valid loss 1.544 | valid acc 0.364 | mae 1.982 | mse 6.908 | rmse 2.63 | r2 -1.32 | sharp 1.50
epoch 17 | time used:  0.20s | train_loss 1.585 | valid loss 1.516 | valid acc 0.364 | mae 1.982 | mse 6.908 | rmse 2.63 | r2 -1.32 | sharp 1.50
epoch 18 | time used:  0.20s | train_loss 1.550 | valid loss 1.566 | valid acc 0.343 | mae 2.018 | mse 7.052 | rmse 2.66 | r2 -1.37 | sharp 0.00
epoch 19 | time used:  0.20s | train_loss 1.551 | valid loss 1.566 | valid acc 0.343 | mae 2.018 | mse 7.052 | rmse 2.66 | r2 -1.37 | sharp 0.00
epoch 20 | time used:  0.20s | train_loss 1.549 | valid loss 1.566 | valid acc 0.343 | mae 2.018 | mse 7.052 | rmse 2.66 | r2 -1.37 | sharp 0.00
saving the model to ./save/2021_500/Attention/checkpoint20.pt
epoch 21 | time used:  0.18s | train_loss 1.550 | valid loss 1.566 | valid acc 0.343 | mae 2.018 | mse 7.052 | rmse 2.66 | r2 -1.37 | sharp 0.00
epoch 22 | time used:  0.17s | train_loss 1.548 | valid loss 1.566 | valid acc 0.343 | mae 2.018 | mse 7.052 | rmse 2.66 | r2 -1.37 | sharp 0.00
epoch 23 | time used:  0.16s | train_loss 1.551 | valid loss 1.566 | valid acc 0.343 | mae 2.018 | mse 7.052 | rmse 2.66 | r2 -1.37 | sharp 0.00
epoch 24 | time used:  0.17s | train_loss 1.548 | valid loss 1.566 | valid acc 0.343 | mae 2.018 | mse 7.052 | rmse 2.66 | r2 -1.37 | sharp 0.00
epoch 25 | time used:  0.16s | train_loss 1.550 | valid loss 1.566 | valid acc 0.343 | mae 2.018 | mse 7.052 | rmse 2.66 | r2 -1.37 | sharp 0.00
epoch 26 | time used:  0.16s | train_loss 1.538 | valid loss 1.507 | valid acc 0.343 | mae 2.018 | mse 7.052 | rmse 2.66 | r2 -1.37 | sharp 0.00
epoch 27 | time used:  0.16s | train_loss 1.526 | valid loss 1.566 | valid acc 0.343 | mae 2.018 | mse 7.052 | rmse 2.66 | r2 -1.37 | sharp 0.00
epoch 28 | time used:  0.16s | train_loss 1.553 | valid loss 1.565 | valid acc 0.343 | mae 2.018 | mse 7.052 | rmse 2.66 | r2 -1.37 | sharp 0.00
epoch 29 | time used:  0.16s | train_loss 1.554 | valid loss 1.543 | valid acc 0.364 | mae 1.982 | mse 6.908 | rmse 2.63 | r2 -1.32 | sharp 1.50
epoch 30 | time used:  0.16s | train_loss 1.627 | valid loss 1.839 | valid acc 0.064 | mae 1.710 | mse 3.944 | rmse 1.99 | r2 -0.32 | sharp 1.50
saving the model to ./save/2021_500/Attention/checkpoint30.pt
epoch 31 | time used:  0.16s | train_loss 1.586 | valid loss 1.566 | valid acc 0.343 | mae 2.018 | mse 7.052 | rmse 2.66 | r2 -1.37 | sharp 0.00
epoch 32 | time used:  0.16s | train_loss 1.550 | valid loss 1.566 | valid acc 0.343 | mae 2.018 | mse 7.052 | rmse 2.66 | r2 -1.37 | sharp 0.00
epoch 33 | time used:  0.18s | train_loss 1.579 | valid loss 1.762 | valid acc 0.141 | mae 1.566 | mse 2.980 | rmse 1.73 | r2 -0.00 | sharp 1.50
epoch 34 | time used:  0.19s | train_loss 1.759 | valid loss 1.762 | valid acc 0.141 | mae 1.566 | mse 2.980 | rmse 1.73 | r2 -0.00 | sharp 1.50
epoch 35 | time used:  0.17s | train_loss 1.558 | valid loss 1.566 | valid acc 0.343 | mae 2.018 | mse 7.052 | rmse 2.66 | r2 -1.37 | sharp 0.00
epoch 36 | time used:  0.18s | train_loss 1.617 | valid loss 1.544 | valid acc 0.364 | mae 1.982 | mse 6.908 | rmse 2.63 | r2 -1.32 | sharp 1.50
epoch 37 | time used:  0.19s | train_loss 1.567 | valid loss 1.544 | valid acc 0.364 | mae 1.982 | mse 6.908 | rmse 2.63 | r2 -1.32 | sharp 1.50
epoch 38 | time used:  0.19s | train_loss 1.585 | valid loss 1.544 | valid acc 0.364 | mae 1.982 | mse 6.908 | rmse 2.63 | r2 -1.32 | sharp 1.50
epoch 39 | time used:  0.18s | train_loss 1.584 | valid loss 1.544 | valid acc 0.364 | mae 1.982 | mse 6.908 | rmse 2.63 | r2 -1.32 | sharp 1.50
epoch 40 | time used:  0.17s | train_loss 1.585 | valid loss 1.543 | valid acc 0.364 | mae 1.982 | mse 6.908 | rmse 2.63 | r2 -1.32 | sharp 1.50
